Workbook

Sheet คู่มือการใช้งาน
A1: ระบบคำนวณคะแนนทายผลฟุตบอลโลก 2026 (สำหรับนำไปใช้บน AppSheet)
A3: โครงสร้างตารางนี้ออกแบบมาเพื่อให้คุณสามารถใช้เป็นฐานข้อมูล (Database) บน Google Sheets เพื่อเชื่อมต่อกับ AppSheet ได้ทันที
A5: คำชี้แจงในแต่ละแท็บ:
A6: 1. แท็บ 'Matches (สำหรับแอดมิน)' | B6: : สำหรับให้แอดมินใส่ตารางแข่งล่วงหน้า เมื่อแข่งจบให้แอดมินมาเติม Score_A, Score_B และเปลี่ยนสถานะเป็น 'จบแล้ว'
A7: 2. แท็บ 'Predictions (ทายผล)' | B7: : สำหรับเก็บข้อมูลที่ผู้ใช้ทายผล (บน AppSheet คอลัมน์ Points_Earned จะใช้สูตรคำนวณให้เปิดดูตารางนี้เป็นตัวอย่าง)
A8: 3. แท็บ 'Leaderboard (คะแนนรวม)' | B8: : ตารางสรุปคะแนนรวมของ User แต่ละคน โดยใช้สูตรดึงคะแนนรวมมาจากแท็บทายผลอัตโนมัติ
A10: กฎการคิดคะแนนตามที่คุณกำหนด:
A11: - ทายผล แพ้/ชนะ/เสมอ ถูกต้อง | B11: : ได้รับ 3 คะแนน
A12: - โบนัสทายสกอร์ถูกเป๊ะ | B12: : ได้รับเพิ่มตามผลรวมประตูของแมตช์นั้น (เช่น ผล 2-3 ทายถูกเป๊ะ ได้ 3 + 2 + 3 = 8 คะแนน)
A13: - กรณีผลจริงเสมอ 0-0 | B13: : หากทายถูกเป๊ะ 0-0 จะได้ 3 + 0 + 0 = 3 คะแนนพอดีตามกฎ

Sheet Matches (สำหรับแอดมิน)
A1: Match_ID | B1: Date | C1: Team_A | D1: Team_B | E1: Score_A | F1: Score_B | G1: Status | H1: Venue | I1: City
A2: 1 | B2: 46184.625 | C2: Mexico | D2: South Africa | G2: ยังไม่แข่ง | H2: Estadio Azteca | I2: Mexico City
A3: 2 | B3: 46184.917 | C3: South Korea | D3: Czechia | G3: ยังไม่แข่ง | H3: Estadio Akron | I3: Guadalajara
A4: 3 | B4: 46185.625 | C4: Canada | D4: Bosnia | G4: ยังไม่แข่ง | H4: BMO Field | I4: Toronto
A5: 4 | B5: 46185.875 | C5: United States | D5: Paraguay | G5: ยังไม่แข่ง | H5: SoFi Stadium | I5: Los Angeles
A6: 5 | B6: 46186.625 | C6: Qatar | D6: Switzerland | G6: ยังไม่แข่ง | H6: Levi's Stadium | I6: San Francisco
A7: 6 | B7: 46186.75 | C7: Brazil | D7: Morocco | G7: ยังไม่แข่ง | H7: MetLife Stadium | I7: New York/NJ
A8: 7 | B8: 46186.875 | C8: Haiti | D8: Scotland | G8: ยังไม่แข่ง | H8: Gillette Stadium | I8: Boston
A9: 8 | B9: 46186.999 | C9: Australia | D9: Turkey | G9: ยังไม่แข่ง | H9: BC Place | I9: Vancouver
A10: 9 | B10: 46187.542 | C10: Germany | D10: Curacao | G10: ยังไม่แข่ง | H10: NRG Stadium | I10: Houston
A11: 10 | B11: 46187.667 | C11: Netherlands | D11: Japan | G11: ยังไม่แข่ง | H11: AT&T Stadium | I11: Dallas
A12: 11 | B12: 46187.792 | C12: Ivory Coast | D12: Ecuador | G12: ยังไม่แข่ง | H12: Lincoln Financial Field | I12: Philadelphia
A13: 12 | B13: 46187.917 | C13: Sweden | D13: Tunisia | G13: ยังไม่แข่ง | H13: Estadio BBVA | I13: Monterrey
... A105: 104 | B105: 46222.625 | C105: W191 | D105: W102 | G105: ยังไม่แข่ง | H105: MetLife Stadium | I105: New York/NJ

Sheet Predictions (ทายผล)
A1: Prediction_ID | B1: User_Email | C1: Match_ID | D1: Team_A | E1: Predict_A | F1: Team_B | G1: Predict_B | H1: Points | I1: Last_Updated_By | J1: Last_Updated_At
A2: =B2&"_M"&C2 -> Ball_M1 | B2: Ball | C2: 1 | D2: =VLOOKUP(C2,'Matches (สำหรับแอดมิน)'!$A$2:$D$105,3,FALSE) -> Mexico | E2: 2 | F2: =VLOOKUP(C2,'Matches (สำหรับแอดมิน)'!$A$2:$D$105,4,FALSE) -> South Africa | G2: 0 | H2: =IF(VLOOKUP(C2,'Matches (สำหรับแอดมิน)'!$A$2:$G$100,7,FALSE)<>"จบแล้ว",0, IF( AND( E2=VLOOKUP(C2,'Matches (สำหรับแอดมิน)'!$A$2:$G$100,5,FALSE), G2=VLOOKUP(C2,'Matches (สำหรับแอดมิน)'!$A$2:$G$100,6,FALSE) ), IF( AND( VLOOKUP(C2,'Matches (สำหรับแอดมิน)'!$A$2:$G$100,5,FALSE)=0, VLOOKUP(C2,'Matches (สำหรับแอดมิน)'!$A$2:$G$100,6,FALSE)=0 ), 4, 3+ VLOOKUP(C2,'Matches (สำหรับแอดมิน)'!$A$2:$G$100,5,FALSE)+ VLOOKUP(C2,'Matches (สำหรับแอดมิน)'!$A$2:$G$100,6,FALSE) ), IF( OR( AND( VLOOKUP(C2,'Matches (สำหรับแอดมิน)'!$A$2:$G$100,5,FALSE)> VLOOKUP(C2,'Matches (สำหรับแอดมิน)'!$A$2:$G$100,6,FALSE), E2>G2 ), AND( VLOOKUP(C2,'Matches (สำหรับแอดมิน)'!$A$2:$G$100,6,FALSE)> VLOOKUP(C2,'Matches (สำหรับแอดมิน)'!$A$2:$G$100,5,FALSE), G2>E2 ), AND( VLOOKUP(C2,'Matches (สำหรับแอดมิน)'!$A$2:$G$100,5,FALSE)= VLOOKUP(C2,'Matches (สำหรับแอดมิน)'!$A$2:$G$100,6,FALSE), E2=G2 ) ), 3, 0 ) )) -> 0
A3: =B3&"_M"&C3 -> Been_M1 | B3: Been | C3: 1 | D3: =VLOOKUP(C3,'Matches (สำหรับแอดมิน)'!$A$2:$D$105,3,FALSE) -> Mexico | F3: =VLOOKUP(C3,'Matches (สำหรับแอดมิน)'!$A$2:$D$105,4,FALSE) -> South Africa | H3: =IF(VLOOKUP(C3,'Matches (สำหรับแอดมิน)'!$A$2:$G$100,7,FALSE)<>"จบแล้ว",0, IF( AND( E3=VLOOKUP(C3,'Matches (สำหรับแอดมิน)'!$A$2:$G$100,5,FALSE), G3=VLOOKUP(C3,'Matches (สำหรับแอดมิน)'!$A$2:$G$100,6,FALSE) ), IF( AND( VLOOKUP(C3,'Matches (สำหรับแอดมิน)'!$A$2:$G$100,5,FALSE)=0, VLOOKUP(C3,'Matches (สำหรับแอดมิน)'!$A$2:$G$100,6,FALSE)=0 ), 4, 3+ VLOOKUP(C3,'Matches (สำหรับแอดมิน)'!$A$2:$G$100,5,FALSE)+ VLOOKUP(C3,'Matches (สำหรับแอดมิน)'!$A$2:$G$100,6,FALSE) ), IF( OR( AND( VLOOKUP(C3,'Matches (สำหรับแอดมิน)'!$A$2:$G$100,5,FALSE)> VLOOKUP(C3,'Matches (สำหรับแอดมิน)'!$A$2:$G$100,6,FALSE), E3>G3 ), AND( VLOOKUP(C3,'Matches (สำหรับแอดมิน)'!$A$2:$G$100,6,FALSE)> VLOOKUP(C3,'Matches (สำหรับแอดมิน)'!$A$2:$G$100,5,FALSE), G3>E3 ), AND( VLOOKUP(C3,'Matches (สำหรับแอดมิน)'!$A$2:$G$100,5,FALSE)= VLOOKUP(C3,'Matches (สำหรับแอดมิน)'!$A$2:$G$100,6,FALSE), E3=G3 ) ), 3, 0 ) )) -> 0
A4: =B4&"_M"&C4 -> Faro_M1 | B4: Faro | C4: 1 | D4: =VLOOKUP(C4,'Matches (สำหรับแอดมิน)'!$A$2:$D$105,3,FALSE) -> Mexico | E4: 2 | F4: =VLOOKUP(C4,'Matches (สำหรับแอดมิน)'!$A$2:$D$105,4,FALSE) -> South Africa | G4: 0 | H4: =IF(VLOOKUP(C4,'Matches (สำหรับแอดมิน)'!$A$2:$G$100,7,FALSE)<>"จบแล้ว",0, IF( AND( E4=VLOOKUP(C4,'Matches (สำหรับแอดมิน)'!$A$2:$G$100,5,FALSE), G4=VLOOKUP(C4,'Matches (สำหรับแอดมิน)'!$A$2:$G$100,6,FALSE) ), IF( AND( VLOOKUP(C4,'Matches (สำหรับแอดมิน)'!$A$2:$G$100,5,FALSE)=0, VLOOKUP(C4,'Matches (สำหรับแอดมิน)'!$A$2:$G$100,6,FALSE)=0 ), 4, 3+ VLOOKUP(C4,'Matches (สำหรับแอดมิน)'!$A$2:$G$100,5,FALSE)+ VLOOKUP(C4,'Matches (สำหรับแอดมิน)'!$A$2:$G$100,6,FALSE) ), IF( OR( AND( VLOOKUP(C4,'Matches (สำหรับแอดมิน)'!$A$2:$G$100,5,FALSE)> VLOOKUP(C4,'Matches (สำหรับแอดมิน)'!$A$2:$G$100,6,FALSE), E4>G4 ), AND( VLOOKUP(C4,'Matches (สำหรับแอดมิน)'!$A$2:$G$100,6,FALSE)> VLOOKUP(C4,'Matches (สำหรับแอดมิน)'!$A$2:$G$100,5,FALSE), G4>E4 ), AND( VLOOKUP(C4,'Matches (สำหรับแอดมิน)'!$A$2:$G$100,5,FALSE)= VLOOKUP(C4,'Matches (สำหรับแอดมิน)'!$A$2:$G$100,6,FALSE), E4=G4 ) ), 3, 0 ) )) -> 0
A5: =B5&"_M"&C5 -> Oat_M1 | B5: Oat | C5: 1 | D5: =VLOOKUP(C5,'Matches (สำหรับแอดมิน)'!$A$2:$D$105,3,FALSE) -> Mexico | E5: 1 | F5: =VLOOKUP(C5,'Matches (สำหรับแอดมิน)'!$A$2:$D$105,4,FALSE) -> South Africa | G5: 1 | H5: =IF(VLOOKUP(C5,'Matches (สำหรับแอดมิน)'!$A$2:$G$100,7,FALSE)<>"จบแล้ว",0, IF( AND( E5=VLOOKUP(C5,'Matches (สำหรับแอดมิน)'!$A$2:$G$100,5,FALSE), G5=VLOOKUP(C5,'Matches (สำหรับแอดมิน)'!$A$2:$G$100,6,FALSE) ), IF( AND( VLOOKUP(C5,'Matches (สำหรับแอดมิน)'!$A$2:$G$100,5,FALSE)=0, VLOOKUP(C5,'Matches (สำหรับแอดมิน)'!$A$2:$G$100,6,FALSE)=0 ), 4, 3+ VLOOKUP(C5,'Matches (สำหรับแอดมิน)'!$A$2:$G$100,5,FALSE)+ VLOOKUP(C5,'Matches (สำหรับแอดมิน)'!$A$2:$G$100,6,FALSE) ), IF( OR( AND( VLOOKUP(C5,'Matches (สำหรับแอดมิน)'!$A$2:$G$100,5,FALSE)> VLOOKUP(C5,'Matches (สำหรับแอดมิน)'!$A$2:$G$100,6,FALSE), E5>G5 ), AND( VLOOKUP(C5,'Matches (สำหรับแอดมิน)'!$A$2:$G$100,6,FALSE)> VLOOKUP(C5,'Matches (สำหรับแอดมิน)'!$A$2:$G$100,5,FALSE), G5>E5 ), AND( VLOOKUP(C5,'Matches (สำหรับแอดมิน)'!$A$2:$G$100,5,FALSE)= VLOOKUP(C5,'Matches (สำหรับแอดมิน)'!$A$2:$G$100,6,FALSE), E5=G5 ) ), 3, 0 ) )) -> 0
A6: =B6&"_M"&C6 -> Kob_M1 | B6: Kob | C6: 1 | D6: =VLOOKUP(C6,'Matches (สำหรับแอดมิน)'!$A$2:$D$105,3,FALSE) -> Mexico | E6: 2 | F6: =VLOOKUP(C6,'Matches (สำหรับแอดมิน)'!$A$2:$D$105,4,FALSE) -> South Africa | G6: 1 | H6: =IF(VLOOKUP(C6,'Matches (สำหรับแอดมิน)'!$A$2:$G$100,7,FALSE)<>"จบแล้ว",0, IF( AND( E6=VLOOKUP(C6,'Matches (สำหรับแอดมิน)'!$A$2:$G$100,5,FALSE), G6=VLOOKUP(C6,'Matches (สำหรับแอดมิน)'!$A$2:$G$100,6,FALSE) ), IF( AND( VLOOKUP(C6,'Matches (สำหรับแอดมิน)'!$A$2:$G$100,5,FALSE)=0, VLOOKUP(C6,'Matches (สำหรับแอดมิน)'!$A$2:$G$100,6,FALSE)=0 ), 4, 3+ VLOOKUP(C6,'Matches (สำหรับแอดมิน)'!$A$2:$G$100,5,FALSE)+ VLOOKUP(C6,'Matches (สำหรับแอดมิน)'!$A$2:$G$100,6,FALSE) ), IF( OR( AND( VLOOKUP(C6,'Matches (สำหรับแอดมิน)'!$A$2:$G$100,5,FALSE)> VLOOKUP(C6,'Matches (สำหรับแอดมิน)'!$A$2:$G$100,6,FALSE), E6>G6 ), AND( VLOOKUP(C6,'Matches (สำหรับแอดมิน)'!$A$2:$G$100,6,FALSE)> VLOOKUP(C6,'Matches (สำหรับแอดมิน)'!$A$2:$G$100,5,FALSE), G6>E6 ), AND( VLOOKUP(C6,'Matches (สำหรับแอดมิน)'!$A$2:$G$100,5,FALSE)= VLOOKUP(C6,'Matches (สำหรับแอดมิน)'!$A$2:$G$100,6,FALSE), E6=G6 ) ), 3, 0 ) )) -> 0
A7: =B7&"_M"&C7 -> Aof_M1 | B7: Aof | C7: 1 | D7: =VLOOKUP(C7,'Matches (สำหรับแอดมิน)'!$A$2:$D$105,3,FALSE) -> Mexico | E7: 3 | F7: =VLOOKUP(C7,'Matches (สำหรับแอดมิน)'!$A$2:$D$105,4,FALSE) -> South Africa | G7: 2 | H7: =IF(VLOOKUP(C7,'Matches (สำหรับแอดมิน)'!$A$2:$G$100,7,FALSE)<>"จบแล้ว",0, IF( AND( E7=VLOOKUP(C7,'Matches (สำหรับแอดมิน)'!$A$2:$G$100,5,FALSE), G7=VLOOKUP(C7,'Matches (สำหรับแอดมิน)'!$A$2:$G$100,6,FALSE) ), IF( AND( VLOOKUP(C7,'Matches (สำหรับแอดมิน)'!$A$2:$G$100,5,FALSE)=0, VLOOKUP(C7,'Matches (สำหรับแอดมิน)'!$A$2:$G$100,6,FALSE)=0 ), 4, 3+ VLOOKUP(C7,'Matches (สำหรับแอดมิน)'!$A$2:$G$100,5,FALSE)+ VLOOKUP(C7,'Matches (สำหรับแอดมิน)'!$A$2:$G$100,6,FALSE) ), IF( OR( AND( VLOOKUP(C7,'Matches (สำหรับแอดมิน)'!$A$2:$G$100,5,FALSE)> VLOOKUP(C7,'Matches (สำหรับแอดมิน)'!$A$2:$G$100,6,FALSE), E7>G7 ), AND( VLOOKUP(C7,'Matches (สำหรับแอดมิน)'!$A$2:$G$100,6,FALSE)> VLOOKUP(C7,'Matches (สำหรับแอดมิน)'!$A$2:$G$100,5,FALSE), G7>E7 ), AND( VLOOKUP(C7,'Matches (สำหรับแอดมิน)'!$A$2:$G$100,5,FALSE)= VLOOKUP(C7,'Matches (สำหรับแอดมิน)'!$A$2:$G$100,6,FALSE), E7=G7 ) ), 3, 0 ) )) -> 0
A8: =B8&"_M"&C8 -> Ice_M1 | B8: Ice | C8: 1 | D8: =VLOOKUP(C8,'Matches (สำหรับแอดมิน)'!$A$2:$D$105,3,FALSE) -> Mexico | E8: 1 | F8: =VLOOKUP(C8,'Matches (สำหรับแอดมิน)'!$A$2:$D$105,4,FALSE) -> South Africa | G8: 0 | H8: =IF(VLOOKUP(C8,'Matches (สำหรับแอดมิน)'!$A$2:$G$100,7,FALSE)<>"จบแล้ว",0, IF( AND( E8=VLOOKUP(C8,'Matches (สำหรับแอดมิน)'!$A$2:$G$100,5,FALSE), G8=VLOOKUP(C8,'Matches (สำหรับแอดมิน)'!$A$2:$G$100,6,FALSE) ), IF( AND( VLOOKUP(C8,'Matches (สำหรับแอดมิน)'!$A$2:$G$100,5,FALSE)=0, VLOOKUP(C8,'Matches (สำหรับแอดมิน)'!$A$2:$G$100,6,FALSE)=0 ), 4, 3+ VLOOKUP(C8,'Matches (สำหรับแอดมิน)'!$A$2:$G$100,5,FALSE)+ VLOOKUP(C8,'Matches (สำหรับแอดมิน)'!$A$2:$G$100,6,FALSE) ), IF( OR( AND( VLOOKUP(C8,'Matches (สำหรับแอดมิน)'!$A$2:$G$100,5,FALSE)> VLOOKUP(C8,'Matches (สำหรับแอดมิน)'!$A$2:$G$100,6,FALSE), E8>G8 ), AND( VLOOKUP(C8,'Matches (สำหรับแอดมิน)'!$A$2:$G$100,6,FALSE)> VLOOKUP(C8,'Matches (สำหรับแอดมิน)'!$A$2:$G$100,5,FALSE), G8>E8 ), AND( VLOOKUP(C8,'Matches (สำหรับแอดมิน)'!$A$2:$G$100,5,FALSE)= VLOOKUP(C8,'Matches (สำหรับแอดมิน)'!$A$2:$G$100,6,FALSE), E8=G8 ) ), 3, 0 ) )) -> 0 | I8: siriwit.ice@gmail.com | J8: 46184.946
A9: =B9&"_M"&C9 -> Golf_M1 | B9: Golf | C9: 1 | D9: =VLOOKUP(C9,'Matches (สำหรับแอดมิน)'!$A$2:$D$105,3,FALSE) -> Mexico | E9: 2 | F9: =VLOOKUP(C9,'Matches (สำหรับแอดมิน)'!$A$2:$D$105,4,FALSE) -> South Africa | G9: 0 | H9: =IF(VLOOKUP(C9,'Matches (สำหรับแอดมิน)'!$A$2:$G$100,7,FALSE)<>"จบแล้ว",0, IF( AND( E9=VLOOKUP(C9,'Matches (สำหรับแอดมิน)'!$A$2:$G$100,5,FALSE), G9=VLOOKUP(C9,'Matches (สำหรับแอดมิน)'!$A$2:$G$100,6,FALSE) ), IF( AND( VLOOKUP(C9,'Matches (สำหรับแอดมิน)'!$A$2:$G$100,5,FALSE)=0, VLOOKUP(C9,'Matches (สำหรับแอดมิน)'!$A$2:$G$100,6,FALSE)=0 ), 4, 3+ VLOOKUP(C9,'Matches (สำหรับแอดมิน)'!$A$2:$G$100,5,FALSE)+ VLOOKUP(C9,'Matches (สำหรับแอดมิน)'!$A$2:$G$100,6,FALSE) ), IF( OR( AND( VLOOKUP(C9,'Matches (สำหรับแอดมิน)'!$A$2:$G$100,5,FALSE)> VLOOKUP(C9,'Matches (สำหรับแอดมิน)'!$A$2:$G$100,6,FALSE), E9>G9 ), AND( VLOOKUP(C9,'Matches (สำหรับแอดมิน)'!$A$2:$G$100,6,FALSE)> VLOOKUP(C9,'Matches (สำหรับแอดมิน)'!$A$2:$G$100,5,FALSE), G9>E9 ), AND( VLOOKUP(C9,'Matches (สำหรับแอดมิน)'!$A$2:$G$100,5,FALSE)= VLOOKUP(C9,'Matches (สำหรับแอดมิน)'!$A$2:$G$100,6,FALSE), E9=G9 ) ), 3, 0 ) )) -> 0
A10: =B10&"_M"&C10 -> Mun_M1 | B10: Mun | C10: 1 | D10: =VLOOKUP(C10,'Matches (สำหรับแอดมิน)'!$A$2:$D$105,3,FALSE) -> Mexico | F10: =VLOOKUP(C10,'Matches (สำหรับแอดมิน)'!$A$2:$D$105,4,FALSE) -> South Africa | H10: =IF(VLOOKUP(C10,'Matches (สำหรับแอดมิน)'!$A$2:$G$100,7,FALSE)<>"จบแล้ว",0, IF( AND( E10=VLOOKUP(C10,'Matches (สำหรับแอดมิน)'!$A$2:$G$100,5,FALSE), G10=VLOOKUP(C10,'Matches (สำหรับแอดมิน)'!$A$2:$G$100,6,FALSE) ), IF( AND( VLOOKUP(C10,'Matches (สำหรับแอดมิน)'!$A$2:$G$100,5,FALSE)=0, VLOOKUP(C10,'Matches (สำหรับแอดมิน)'!$A$2:$G$100,6,FALSE)=0 ), 4, 3+ VLOOKUP(C10,'Matches (สำหรับแอดมิน)'!$A$2:$G$100,5,FALSE)+ VLOOKUP(C10,'Matches (สำหรับแอดมิน)'!$A$2:$G$100,6,FALSE) ), IF( OR( AND( VLOOKUP(C10,'Matches (สำหรับแอดมิน)'!$A$2:$G$100,5,FALSE)> VLOOKUP(C10,'Matches (สำหรับแอดมิน)'!$A$2:$G$100,6,FALSE), E10>G10 ), AND( VLOOKUP(C10,'Matches (สำหรับแอดมิน)'!$A$2:$G$100,6,FALSE)> VLOOKUP(C10,'Matches (สำหรับแอดมิน)'!$A$2:$G$100,5,FALSE), G10>E10 ), AND( VLOOKUP(C10,'Matches (สำหรับแอดมิน)'!$A$2:$G$100,5,FALSE)= VLOOKUP(C10,'Matches (สำหรับแอดมิน)'!$A$2:$G$100,6,FALSE), E10=G10 ) ), 3, 0 ) )) -> 0
A11: =B11&"_M"&C11 -> Mig_M1 | B11: Mig | C11: 1 | D11: =VLOOKUP(C11,'Matches (สำหรับแอดมิน)'!$A$2:$D$105,3,FALSE) -> Mexico | F11: =VLOOKUP(C11,'Matches (สำหรับแอดมิน)'!$A$2:$D$105,4,FALSE) -> South Africa | H11: =IF(VLOOKUP(C11,'Matches (สำหรับแอดมิน)'!$A$2:$G$100,7,FALSE)<>"จบแล้ว",0, IF( AND( E11=VLOOKUP(C11,'Matches (สำหรับแอดมิน)'!$A$2:$G$100,5,FALSE), G11=VLOOKUP(C11,'Matches (สำหรับแอดมิน)'!$A$2:$G$100,6,FALSE) ), IF( AND( VLOOKUP(C11,'Matches (สำหรับแอดมิน)'!$A$2:$G$100,5,FALSE)=0, VLOOKUP(C11,'Matches (สำหรับแอดมิน)'!$A$2:$G$100,6,FALSE)=0 ), 4, 3+ VLOOKUP(C11,'Matches (สำหรับแอดมิน)'!$A$2:$G$100,5,FALSE)+ VLOOKUP(C11,'Matches (สำหรับแอดมิน)'!$A$2:$G$100,6,FALSE) ), IF( OR( AND( VLOOKUP(C11,'Matches (สำหรับแอดมิน)'!$A$2:$G$100,5,FALSE)> VLOOKUP(C11,'Matches (สำหรับแอดมิน)'!$A$2:$G$100,6,FALSE), E11>G11 ), AND( VLOOKUP(C11,'Matches (สำหรับแอดมิน)'!$A$2:$G$100,6,FALSE)> VLOOKUP(C11,'Matches (สำหรับแอดมิน)'!$A$2:$G$100,5,FALSE), G11>E11 ), AND( VLOOKUP(C11,'Matches (สำหรับแอดมิน)'!$A$2:$G$100,5,FALSE)= VLOOKUP(C11,'Matches (สำหรับแอดมิน)'!$A$2:$G$100,6,FALSE), E11=G11 ) ), 3, 0 ) )) -> 0
A12: =B12&"_M"&C12 -> Ball_M2 | B12: Ball | C12: 2 | D12: =VLOOKUP(C12,'Matches (สำหรับแอดมิน)'!$A$2:$D$105,3,FALSE) -> South Korea | E12: 3 | F12: =VLOOKUP(C12,'Matches (สำหรับแอดมิน)'!$A$2:$D$105,4,FALSE) -> Czechia | G12: 1 | H12: =IF(VLOOKUP(C12,'Matches (สำหรับแอดมิน)'!$A$2:$G$100,7,FALSE)<>"จบแล้ว",0, IF( AND( E12=VLOOKUP(C12,'Matches (สำหรับแอดมิน)'!$A$2:$G$100,5,FALSE), G12=VLOOKUP(C12,'Matches (สำหรับแอดมิน)'!$A$2:$G$100,6,FALSE) ), IF( AND( VLOOKUP(C12,'Matches (สำหรับแอดมิน)'!$A$2:$G$100,5,FALSE)=0, VLOOKUP(C12,'Matches (สำหรับแอดมิน)'!$A$2:$G$100,6,FALSE)=0 ), 4, 3+ VLOOKUP(C12,'Matches (สำหรับแอดมิน)'!$A$2:$G$100,5,FALSE)+ VLOOKUP(C12,'Matches (สำหรับแอดมิน)'!$A$2:$G$100,6,FALSE) ), IF( OR( AND( VLOOKUP(C12,'Matches (สำหรับแอดมิน)'!$A$2:$G$100,5,FALSE)> VLOOKUP(C12,'Matches (สำหรับแอดมิน)'!$A$2:$G$100,6,FALSE), E12>G12 ), AND( VLOOKUP(C12,'Matches (สำหรับแอดมิน)'!$A$2:$G$100,6,FALSE)> VLOOKUP(C12,'Matches (สำหรับแอดมิน)'!$A$2:$G$100,5,FALSE), G12>E12 ), AND( VLOOKUP(C12,'Matches (สำหรับแอดมิน)'!$A$2:$G$100,5,FALSE)= VLOOKUP(C12,'Matches (สำหรับแอดมิน)'!$A$2:$G$100,6,FALSE), E12=G12 ) ), 3, 0 ) )) -> 0
A13: =B13&"_M"&C13 -> Been_M2 | B13: Been | C13: 2 | D13: =VLOOKUP(C13,'Matches (สำหรับแอดมิน)'!$A$2:$D$105,3,FALSE) -> South Korea | F13: =VLOOKUP(C13,'Matches (สำหรับแอดมิน)'!$A$2:$D$105,4,FALSE) -> Czechia | H13: =IF(VLOOKUP(C13,'Matches (สำหรับแอดมิน)'!$A$2:$G$100,7,FALSE)<>"จบแล้ว",0, IF( AND( E13=VLOOKUP(C13,'Matches (สำหรับแอดมิน)'!$A$2:$G$100,5,FALSE), G13=VLOOKUP(C13,'Matches (สำหรับแอดมิน)'!$A$2:$G$100,6,FALSE) ), IF( AND( VLOOKUP(C13,'Matches (สำหรับแอดมิน)'!$A$2:$G$100,5,FALSE)=0, VLOOKUP(C13,'Matches (สำหรับแอดมิน)'!$A$2:$G$100,6,FALSE)=0 ), 4, 3+ VLOOKUP(C13,'Matches (สำหรับแอดมิน)'!$A$2:$G$100,5,FALSE)+ VLOOKUP(C13,'Matches (สำหรับแอดมิน)'!$A$2:$G$100,6,FALSE) ), IF( OR( AND( VLOOKUP(C13,'Matches (สำหรับแอดมิน)'!$A$2:$G$100,5,FALSE)> VLOOKUP(C13,'Matches (สำหรับแอดมิน)'!$A$2:$G$100,6,FALSE), E13>G13 ), AND( VLOOKUP(C13,'Matches (สำหรับแอดมิน)'!$A$2:$G$100,6,FALSE)> VLOOKUP(C13,'Matches (สำหรับแอดมิน)'!$A$2:$G$100,5,FALSE), G13>E13 ), AND( VLOOKUP(C13,'Matches (สำหรับแอดมิน)'!$A$2:$G$100,5,FALSE)= VLOOKUP(C13,'Matches (สำหรับแอดมิน)'!$A$2:$G$100,6,FALSE), E13=G13 ) ), 3, 0 ) )) -> 0
A14: =B14&"_M"&C14 -> Faro_M2 | B14: Faro | C14: 2 | D14: =VLOOKUP(C14,'Matches (สำหรับแอดมิน)'!$A$2:$D$105,3,FALSE) -> South Korea | E14: 2 | F14: =VLOOKUP(C14,'Matches (สำหรับแอดมิน)'!$A$2:$D$105,4,FALSE) -> Czechia | G14: 2 | H14: =IF(VLOOKUP(C14,'Matches (สำหรับแอดมิน)'!$A$2:$G$100,7,FALSE)<>"จบแล้ว",0, IF( AND( E14=VLOOKUP(C14,'Matches (สำหรับแอดมิน)'!$A$2:$G$100,5,FALSE), G14=VLOOKUP(C14,'Matches (สำหรับแอดมิน)'!$A$2:$G$100,6,FALSE) ), IF( AND( VLOOKUP(C14,'Matches (สำหรับแอดมิน)'!$A$2:$G$100,5,FALSE)=0, VLOOKUP(C14,'Matches (สำหรับแอดมิน)'!$A$2:$G$100,6,FALSE)=0 ), 4, 3+ VLOOKUP(C14,'Matches (สำหรับแอดมิน)'!$A$2:$G$100,5,FALSE)+ VLOOKUP(C14,'Matches (สำหรับแอดมิน)'!$A$2:$G$100,6,FALSE) ), IF( OR( AND( VLOOKUP(C14,'Matches (สำหรับแอดมิน)'!$A$2:$G$100,5,FALSE)> VLOOKUP(C14,'Matches (สำหรับแอดมิน)'!$A$2:$G$100,6,FALSE), E14>G14 ), AND( VLOOKUP(C14,'Matches (สำหรับแอดมิน)'!$A$2:$G$100,6,FALSE)> VLOOKUP(C14,'Matches (สำหรับแอดมิน)'!$A$2:$G$100,5,FALSE), G14>E14 ), AND( VLOOKUP(C14,'Matches (สำหรับแอดมิน)'!$A$2:$G$100,5,FALSE)= VLOOKUP(C14,'Matches (สำหรับแอดมิน)'!$A$2:$G$100,6,FALSE), E14=G14 ) ), 3, 0 ) )) -> 0
A15: =B15&"_M"&C15 -> Oat_M2 | B15: Oat | C15: 2 | D15: =VLOOKUP(C15,'Matches (สำหรับแอดมิน)'!$A$2:$D$105,3,FALSE) -> South Korea | E15: 1 | F15: =VLOOKUP(C15,'Matches (สำหรับแอดมิน)'!$A$2:$D$105,4,FALSE) -> Czechia | G15: 0 | H15: =IF(VLOOKUP(C15,'Matches (สำหรับแอดมิน)'!$A$2:$G$100,7,FALSE)<>"จบแล้ว",0, IF( AND( E15=VLOOKUP(C15,'Matches (สำหรับแอดมิน)'!$A$2:$G$100,5,FALSE), G15=VLOOKUP(C15,'Matches (สำหรับแอดมิน)'!$A$2:$G$100,6,FALSE) ), IF( AND( VLOOKUP(C15,'Matches (สำหรับแอดมิน)'!$A$2:$G$100,5,FALSE)=0, VLOOKUP(C15,'Matches (สำหรับแอดมิน)'!$A$2:$G$100,6,FALSE)=0 ), 4, 3+ VLOOKUP(C15,'Matches (สำหรับแอดมิน)'!$A$2:$G$100,5,FALSE)+ VLOOKUP(C15,'Matches (สำหรับแอดมิน)'!$A$2:$G$100,6,FALSE) ), IF( OR( AND( VLOOKUP(C15,'Matches (สำหรับแอดมิน)'!$A$2:$G$100,5,FALSE)> VLOOKUP(C15,'Matches (สำหรับแอดมิน)'!$A$2:$G$100,6,FALSE), E15>G15 ), AND( VLOOKUP(C15,'Matches (สำหรับแอดมิน)'!$A$2:$G$100,6,FALSE)> VLOOKUP(C15,'Matches (สำหรับแอดมิน)'!$A$2:$G$100,5,FALSE), G15>E15 ), AND( VLOOKUP(C15,'Matches (สำหรับแอดมิน)'!$A$2:$G$100,5,FALSE)= VLOOKUP(C15,'Matches (สำหรับแอดมิน)'!$A$2:$G$100,6,FALSE), E15=G15 ) ), 3, 0 ) )) -> 0
A16: =B16&"_M"&C16 -> Kob_M2 | B16: Kob | C16: 2 | D16: =VLOOKUP(C16,'Matches (สำหรับแอดมิน)'!$A$2:$D$105,3,FALSE) -> South Korea | E16: 1 | F16: =VLOOKUP(C16,'Matches (สำหรับแอดมิน)'!$A$2:$D$105,4,FALSE) -> Czechia | G16: 0 | H16: =IF(VLOOKUP(C16,'Matches (สำหรับแอดมิน)'!$A$2:$G$100,7,FALSE)<>"จบแล้ว",0, IF( AND( E16=VLOOKUP(C16,'Matches (สำหรับแอดมิน)'!$A$2:$G$100,5,FALSE), G16=VLOOKUP(C16,'Matches (สำหรับแอดมิน)'!$A$2:$G$100,6,FALSE) ), IF( AND( VLOOKUP(C16,'Matches (สำหรับแอดมิน)'!$A$2:$G$100,5,FALSE)=0, VLOOKUP(C16,'Matches (สำหรับแอดมิน)'!$A$2:$G$100,6,FALSE)=0 ), 4, 3+ VLOOKUP(C16,'Matches (สำหรับแอดมิน)'!$A$2:$G$100,5,FALSE)+ VLOOKUP(C16,'Matches (สำหรับแอดมิน)'!$A$2:$G$100,6,FALSE) ), IF( OR( AND( VLOOKUP(C16,'Matches (สำหรับแอดมิน)'!$A$2:$G$100,5,FALSE)> VLOOKUP(C16,'Matches (สำหรับแอดมิน)'!$A$2:$G$100,6,FALSE), E16>G16 ), AND( VLOOKUP(C16,'Matches (สำหรับแอดมิน)'!$A$2:$G$100,6,FALSE)> VLOOKUP(C16,'Matches (สำหรับแอดมิน)'!$A$2:$G$100,5,FALSE), G16>E16 ), AND( VLOOKUP(C16,'Matches (สำหรับแอดมิน)'!$A$2:$G$100,5,FALSE)= VLOOKUP(C16,'Matches (สำหรับแอดมิน)'!$A$2:$G$100,6,FALSE), E16=G16 ) ), 3, 0 ) )) -> 0
A17: =B17&"_M"&C17 -> Aof_M2 | B17: Aof | C17: 2 | D17: =VLOOKUP(C17,'Matches (สำหรับแอดมิน)'!$A$2:$D$105,3,FALSE) -> South Korea | E17: 2 | F17: =VLOOKUP(C17,'Matches (สำหรับแอดมิน)'!$A$2:$D$105,4,FALSE) -> Czechia | G17: 0 | H17: =IF(VLOOKUP(C17,'Matches (สำหรับแอดมิน)'!$A$2:$G$100,7,FALSE)<>"จบแล้ว",0, IF( AND( E17=VLOOKUP(C17,'Matches (สำหรับแอดมิน)'!$A$2:$G$100,5,FALSE), G17=VLOOKUP(C17,'Matches (สำหรับแอดมิน)'!$A$2:$G$100,6,FALSE) ), IF( AND( VLOOKUP(C17,'Matches (สำหรับแอดมิน)'!$A$2:$G$100,5,FALSE)=0, VLOOKUP(C17,'Matches (สำหรับแอดมิน)'!$A$2:$G$100,6,FALSE)=0 ), 4, 3+ VLOOKUP(C17,'Matches (สำหรับแอดมิน)'!$A$2:$G$100,5,FALSE)+ VLOOKUP(C17,'Matches (สำหรับแอดมิน)'!$A$2:$G$100,6,FALSE) ), IF( OR( AND( VLOOKUP(C17,'Matches (สำหรับแอดมิน)'!$A$2:$G$100,5,FALSE)> VLOOKUP(C17,'Matches (สำหรับแอดมิน)'!$A$2:$G$100,6,FALSE), E17>G17 ), AND( VLOOKUP(C17,'Matches (สำหรับแอดมิน)'!$A$2:$G$100,6,FALSE)> VLOOKUP(C17,'Matches (สำหรับแอดมิน)'!$A$2:$G$100,5,FALSE), G17>E17 ), AND( VLOOKUP(C17,'Matches (สำหรับแอดมิน)'!$A$2:$G$100,5,FALSE)= VLOOKUP(C17,'Matches (สำหรับแอดมิน)'!$A$2:$G$100,6,FALSE), E17=G17 ) ), 3, 0 ) )) -> 0
A18: =B18&"_M"&C18 -> Ice_M2 | B18: Ice | C18: 2 | D18: =VLOOKUP(C18,'Matches (สำหรับแอดมิน)'!$A$2:$D$105,3,FALSE) -> South Korea | E18: 0 | F18: =VLOOKUP(C18,'Matches (สำหรับแอดมิน)'!$A$2:$D$105,4,FALSE) -> Czechia | G18: 0 | H18: =IF(VLOOKUP(C18,'Matches (สำหรับแอดมิน)'!$A$2:$G$100,7,FALSE)<>"จบแล้ว",0, IF( AND( E18=VLOOKUP(C18,'Matches (สำหรับแอดมิน)'!$A$2:$G$100,5,FALSE), G18=VLOOKUP(C18,'Matches (สำหรับแอดมิน)'!$A$2:$G$100,6,FALSE) ), IF( AND( VLOOKUP(C18,'Matches (สำหรับแอดมิน)'!$A$2:$G$100,5,FALSE)=0, VLOOKUP(C18,'Matches (สำหรับแอดมิน)'!$A$2:$G$100,6,FALSE)=0 ), 4, 3+ VLOOKUP(C18,'Matches (สำหรับแอดมิน)'!$A$2:$G$100,5,FALSE)+ VLOOKUP(C18,'Matches (สำหรับแอดมิน)'!$A$2:$G$100,6,FALSE) ), IF( OR( AND( VLOOKUP(C18,'Matches (สำหรับแอดมิน)'!$A$2:$G$100,5,FALSE)> VLOOKUP(C18,'Matches (สำหรับแอดมิน)'!$A$2:$G$100,6,FALSE), E18>G18 ), AND( VLOOKUP(C18,'Matches (สำหรับแอดมิน)'!$A$2:$G$100,6,FALSE)> VLOOKUP(C18,'Matches (สำหรับแอดมิน)'!$A$2:$G$100,5,FALSE), G18>E18 ), AND( VLOOKUP(C18,'Matches (สำหรับแอดมิน)'!$A$2:$G$100,5,FALSE)= VLOOKUP(C18,'Matches (สำหรับแอดมิน)'!$A$2:$G$100,6,FALSE), E18=G18 ) ), 3, 0 ) )) -> 0 | I18: siriwit.ice@gmail.com | J18: 46184.948
A19: =B19&"_M"&C19 -> Golf_M2 | B19: Golf | C19: 2 | D19: =VLOOKUP(C19,'Matches (สำหรับแอดมิน)'!$A$2:$D$105,3,FALSE) -> South Korea | E19: 1 | F19: =VLOOKUP(C19,'Matches (สำหรับแอดมิน)'!$A$2:$D$105,4,FALSE) -> Czechia | G19: 2 | H19: =IF(VLOOKUP(C19,'Matches (สำหรับแอดมิน)'!$A$2:$G$100,7,FALSE)<>"จบแล้ว",0, IF( AND( E19=VLOOKUP(C19,'Matches (สำหรับแอดมิน)'!$A$2:$G$100,5,FALSE), G19=VLOOKUP(C19,'Matches (สำหรับแอดมิน)'!$A$2:$G$100,6,FALSE) ), IF( AND( VLOOKUP(C19,'Matches (สำหรับแอดมิน)'!$A$2:$G$100,5,FALSE)=0, VLOOKUP(C19,'Matches (สำหรับแอดมิน)'!$A$2:$G$100,6,FALSE)=0 ), 4, 3+ VLOOKUP(C19,'Matches (สำหรับแอดมิน)'!$A$2:$G$100,5,FALSE)+ VLOOKUP(C19,'Matches (สำหรับแอดมิน)'!$A$2:$G$100,6,FALSE) ), IF( OR( AND( VLOOKUP(C19,'Matches (สำหรับแอดมิน)'!$A$2:$G$100,5,FALSE)> VLOOKUP(C19,'Matches (สำหรับแอดมิน)'!$A$2:$G$100,6,FALSE), E19>G19 ), AND( VLOOKUP(C19,'Matches (สำหรับแอดมิน)'!$A$2:$G$100,6,FALSE)> VLOOKUP(C19,'Matches (สำหรับแอดมิน)'!$A$2:$G$100,5,FALSE), G19>E19 ), AND( VLOOKUP(C19,'Matches (สำหรับแอดมิน)'!$A$2:$G$100,5,FALSE)= VLOOKUP(C19,'Matches (สำหรับแอดมิน)'!$A$2:$G$100,6,FALSE), E19=G19 ) ), 3, 0 ) )) -> 0
A20: =B20&"_M"&C20 -> Mun_M2 | B20: Mun | C20: 2 | D20: =VLOOKUP(C20,'Matches (สำหรับแอดมิน)'!$A$2:$D$105,3,FALSE) -> South Korea | F20: =VLOOKUP(C20,'Matches (สำหรับแอดมิน)'!$A$2:$D$105,4,FALSE) -> Czechia | H20: =IF(VLOOKUP(C20,'Matches (สำหรับแอดมิน)'!$A$2:$G$100,7,FALSE)<>"จบแล้ว",0, IF( AND( E20=VLOOKUP(C20,'Matches (สำหรับแอดมิน)'!$A$2:$G$100,5,FALSE), G20=VLOOKUP(C20,'Matches (สำหรับแอดมิน)'!$A$2:$G$100,6,FALSE) ), IF( AND( VLOOKUP(C20,'Matches (สำหรับแอดมิน)'!$A$2:$G$100,5,FALSE)=0, VLOOKUP(C20,'Matches (สำหรับแอดมิน)'!$A$2:$G$100,6,FALSE)=0 ), 4, 3+ VLOOKUP(C20,'Matches (สำหรับแอดมิน)'!$A$2:$G$100,5,FALSE)+ VLOOKUP(C20,'Matches (สำหรับแอดมิน)'!$A$2:$G$100,6,FALSE) ), IF( OR( AND( VLOOKUP(C20,'Matches (สำหรับแอดมิน)'!$A$2:$G$100,5,FALSE)> VLOOKUP(C20,'Matches (สำหรับแอดมิน)'!$A$2:$G$100,6,FALSE), E20>G20 ), AND( VLOOKUP(C20,'Matches (สำหรับแอดมิน)'!$A$2:$G$100,6,FALSE)> VLOOKUP(C20,'Matches (สำหรับแอดมิน)'!$A$2:$G$100,5,FALSE), G20>E20 ), AND( VLOOKUP(C20,'Matches (สำหรับแอดมิน)'!$A$2:$G$100,5,FALSE)= VLOOKUP(C20,'Matches (สำหรับแอดมิน)'!$A$2:$G$100,6,FALSE), E20=G20 ) ), 3, 0 ) )) -> 0
A21: =B21&"_M"&C21 -> Mig_M2 | B21: Mig | C21: 2 | D21: =VLOOKUP(C21,'Matches (สำหรับแอดมิน)'!$A$2:$D$105,3,FALSE) -> South Korea | F21: =VLOOKUP(C21,'Matches (สำหรับแอดมิน)'!$A$2:$D$105,4,FALSE) -> Czechia | H21: =IF(VLOOKUP(C21,'Matches (สำหรับแอดมิน)'!$A$2:$G$100,7,FALSE)<>"จบแล้ว",0, IF( AND( E21=VLOOKUP(C21,'Matches (สำหรับแอดมิน)'!$A$2:$G$100,5,FALSE), G21=VLOOKUP(C21,'Matches (สำหรับแอดมิน)'!$A$2:$G$100,6,FALSE) ), IF( AND( VLOOKUP(C21,'Matches (สำหรับแอดมิน)'!$A$2:$G$100,5,FALSE)=0, VLOOKUP(C21,'Matches (สำหรับแอดมิน)'!$A$2:$G$100,6,FALSE)=0 ), 4, 3+ VLOOKUP(C21,'Matches (สำหรับแอดมิน)'!$A$2:$G$100,5,FALSE)+ VLOOKUP(C21,'Matches (สำหรับแอดมิน)'!$A$2:$G$100,6,FALSE) ), IF( OR( AND( VLOOKUP(C21,'Matches (สำหรับแอดมิน)'!$A$2:$G$100,5,FALSE)> VLOOKUP(C21,'Matches (สำหรับแอดมิน)'!$A$2:$G$100,6,FALSE), E21>G21 ), AND( VLOOKUP(C21,'Matches (สำหรับแอดมิน)'!$A$2:$G$100,6,FALSE)> VLOOKUP(C21,'Matches (สำหรับแอดมิน)'!$A$2:$G$100,5,FALSE), G21>E21 ), AND( VLOOKUP(C21,'Matches (สำหรับแอดมิน)'!$A$2:$G$100,5,FALSE)= VLOOKUP(C21,'Matches (สำหรับแอดมิน)'!$A$2:$G$100,6,FALSE), E21=G21 ) ), 3, 0 ) )) -> 0
A22: =B22&"_M"&C22 -> Ball_M3 | B22: Ball | C22: 3 | D22: =VLOOKUP(C22,'Matches (สำหรับแอดมิน)'!$A$2:$D$105,3,FALSE) -> Canada | F22: =VLOOKUP(C22,'Matches (สำหรับแอดมิน)'!$A$2:$D$105,4,FALSE) -> Bosnia | H22: =IF(VLOOKUP(C22,'Matches (สำหรับแอดมิน)'!$A$2:$G$100,7,FALSE)<>"จบแล้ว",0, IF( AND( E22=VLOOKUP(C22,'Matches (สำหรับแอดมิน)'!$A$2:$G$100,5,FALSE), G22=VLOOKUP(C22,'Matches (สำหรับแอดมิน)'!$A$2:$G$100,6,FALSE) ), IF( AND( VLOOKUP(C22,'Matches (สำหรับแอดมิน)'!$A$2:$G$100,5,FALSE)=0, VLOOKUP(C22,'Matches (สำหรับแอดมิน)'!$A$2:$G$100,6,FALSE)=0 ), 4, 3+ VLOOKUP(C22,'Matches (สำหรับแอดมิน)'!$A$2:$G$100,5,FALSE)+ VLOOKUP(C22,'Matches (สำหรับแอดมิน)'!$A$2:$G$100,6,FALSE) ), IF( OR( AND( VLOOKUP(C22,'Matches (สำหรับแอดมิน)'!$A$2:$G$100,5,FALSE)> VLOOKUP(C22,'Matches (สำหรับแอดมิน)'!$A$2:$G$100,6,FALSE), E22>G22 ), AND( VLOOKUP(C22,'Matches (สำหรับแอดมิน)'!$A$2:$G$100,6,FALSE)> VLOOKUP(C22,'Matches (สำหรับแอดมิน)'!$A$2:$G$100,5,FALSE), G22>E22 ), AND( VLOOKUP(C22,'Matches (สำหรับแอดมิน)'!$A$2:$G$100,5,FALSE)= VLOOKUP(C22,'Matches (สำหรับแอดมิน)'!$A$2:$G$100,6,FALSE), E22=G22 ) ), 3, 0 ) )) -> 0
A23: =B23&"_M"&C23 -> Been_M3 | B23: Been | C23: 3 | D23: =VLOOKUP(C23,'Matches (สำหรับแอดมิน)'!$A$2:$D$105,3,FALSE) -> Canada | F23: =VLOOKUP(C23,'Matches (สำหรับแอดมิน)'!$A$2:$D$105,4,FALSE) -> Bosnia | H23: =IF(VLOOKUP(C23,'Matches (สำหรับแอดมิน)'!$A$2:$G$100,7,FALSE)<>"จบแล้ว",0, IF( AND( E23=VLOOKUP(C23,'Matches (สำหรับแอดมิน)'!$A$2:$G$100,5,FALSE), G23=VLOOKUP(C23,'Matches (สำหรับแอดมิน)'!$A$2:$G$100,6,FALSE) ), IF( AND( VLOOKUP(C23,'Matches (สำหรับแอดมิน)'!$A$2:$G$100,5,FALSE)=0, VLOOKUP(C23,'Matches (สำหรับแอดมิน)'!$A$2:$G$100,6,FALSE)=0 ), 4, 3+ VLOOKUP(C23,'Matches (สำหรับแอดมิน)'!$A$2:$G$100,5,FALSE)+ VLOOKUP(C23,'Matches (สำหรับแอดมิน)'!$A$2:$G$100,6,FALSE) ), IF( OR( AND( VLOOKUP(C23,'Matches (สำหรับแอดมิน)'!$A$2:$G$100,5,FALSE)> VLOOKUP(C23,'Matches (สำหรับแอดมิน)'!$A$2:$G$100,6,FALSE), E23>G23 ), AND( VLOOKUP(C23,'Matches (สำหรับแอดมิน)'!$A$2:$G$100,6,FALSE)> VLOOKUP(C23,'Matches (สำหรับแอดมิน)'!$A$2:$G$100,5,FALSE), G23>E23 ), AND( VLOOKUP(C23,'Matches (สำหรับแอดมิน)'!$A$2:$G$100,5,FALSE)= VLOOKUP(C23,'Matches (สำหรับแอดมิน)'!$A$2:$G$100,6,FALSE), E23=G23 ) ), 3, 0 ) )) -> 0
A24: =B24&"_M"&C24 -> Faro_M3 | B24: Faro | C24: 3 | D24: =VLOOKUP(C24,'Matches (สำหรับแอดมิน)'!$A$2:$D$105,3,FALSE) -> Canada | E24: 2 | F24: =VLOOKUP(C24,'Matches (สำหรับแอดมิน)'!$A$2:$D$105,4,FALSE) -> Bosnia | G24: 1 | H24: =IF(VLOOKUP(C24,'Matches (สำหรับแอดมิน)'!$A$2:$G$100,7,FALSE)<>"จบแล้ว",0, IF( AND( E24=VLOOKUP(C24,'Matches (สำหรับแอดมิน)'!$A$2:$G$100,5,FALSE), G24=VLOOKUP(C24,'Matches (สำหรับแอดมิน)'!$A$2:$G$100,6,FALSE) ), IF( AND( VLOOKUP(C24,'Matches (สำหรับแอดมิน)'!$A$2:$G$100,5,FALSE)=0, VLOOKUP(C24,'Matches (สำหรับแอดมิน)'!$A$2:$G$100,6,FALSE)=0 ), 4, 3+ VLOOKUP(C24,'Matches (สำหรับแอดมิน)'!$A$2:$G$100,5,FALSE)+ VLOOKUP(C24,'Matches (สำหรับแอดมิน)'!$A$2:$G$100,6,FALSE) ), IF( OR( AND( VLOOKUP(C24,'Matches (สำหรับแอดมิน)'!$A$2:$G$100,5,FALSE)> VLOOKUP(C24,'Matches (สำหรับแอดมิน)'!$A$2:$G$100,6,FALSE), E24>G24 ), AND( VLOOKUP(C24,'Matches (สำหรับแอดมิน)'!$A$2:$G$100,6,FALSE)> VLOOKUP(C24,'Matches (สำหรับแอดมิน)'!$A$2:$G$100,5,FALSE), G24>E24 ), AND( VLOOKUP(C24,'Matches (สำหรับแอดมิน)'!$A$2:$G$100,5,FALSE)= VLOOKUP(C24,'Matches (สำหรับแอดมิน)'!$A$2:$G$100,6,FALSE), E24=G24 ) ), 3, 0 ) )) -> 0
A25: =B25&"_M"&C25 -> Oat_M3 | B25: Oat | C25: 3 | D25: =VLOOKUP(C25,'Matches (สำหรับแอดมิน)'!$A$2:$D$105,3,FALSE) -> Canada | E25: 1 | F25: =VLOOKUP(C25,'Matches (สำหรับแอดมิน)'!$A$2:$D$105,4,FALSE) -> Bosnia | G25: 0 | H25: =IF(VLOOKUP(C25,'Matches (สำหรับแอดมิน)'!$A$2:$G$100,7,FALSE)<>"จบแล้ว",0, IF( AND( E25=VLOOKUP(C25,'Matches (สำหรับแอดมิน)'!$A$2:$G$100,5,FALSE), G25=VLOOKUP(C25,'Matches (สำหรับแอดมิน)'!$A$2:$G$100,6,FALSE) ), IF( AND( VLOOKUP(C25,'Matches (สำหรับแอดมิน)'!$A$2:$G$100,5,FALSE)=0, VLOOKUP(C25,'Matches (สำหรับแอดมิน)'!$A$2:$G$100,6,FALSE)=0 ), 4, 3+ VLOOKUP(C25,'Matches (สำหรับแอดมิน)'!$A$2:$G$100,5,FALSE)+ VLOOKUP(C25,'Matches (สำหรับแอดมิน)'!$A$2:$G$100,6,FALSE) ), IF( OR( AND( VLOOKUP(C25,'Matches (สำหรับแอดมิน)'!$A$2:$G$100,5,FALSE)> VLOOKUP(C25,'Matches (สำหรับแอดมิน)'!$A$2:$G$100,6,FALSE), E25>G25 ), AND( VLOOKUP(C25,'Matches (สำหรับแอดมิน)'!$A$2:$G$100,6,FALSE)> VLOOKUP(C25,'Matches (สำหรับแอดมิน)'!$A$2:$G$100,5,FALSE), G25>E25 ), AND( VLOOKUP(C25,'Matches (สำหรับแอดมิน)'!$A$2:$G$100,5,FALSE)= VLOOKUP(C25,'Matches (สำหรับแอดมิน)'!$A$2:$G$100,6,FALSE), E25=G25 ) ), 3, 0 ) )) -> 0
A26: =B26&"_M"&C26 -> Kob_M3 | B26: Kob | C26: 3 | D26: =VLOOKUP(C26,'Matches (สำหรับแอดมิน)'!$A$2:$D$105,3,FALSE) -> Canada | E26: 1 | F26: =VLOOKUP(C26,'Matches (สำหรับแอดมิน)'!$A$2:$D$105,4,FALSE) -> Bosnia | G26: 3 | H26: =IF(VLOOKUP(C26,'Matches (สำหรับแอดมิน)'!$A$2:$G$100,7,FALSE)<>"จบแล้ว",0, IF( AND( E26=VLOOKUP(C26,'Matches (สำหรับแอดมิน)'!$A$2:$G$100,5,FALSE), G26=VLOOKUP(C26,'Matches (สำหรับแอดมิน)'!$A$2:$G$100,6,FALSE) ), IF( AND( VLOOKUP(C26,'Matches (สำหรับแอดมิน)'!$A$2:$G$100,5,FALSE)=0, VLOOKUP(C26,'Matches (สำหรับแอดมิน)'!$A$2:$G$100,6,FALSE)=0 ), 4, 3+ VLOOKUP(C26,'Matches (สำหรับแอดมิน)'!$A$2:$G$100,5,FALSE)+ VLOOKUP(C26,'Matches (สำหรับแอดมิน)'!$A$2:$G$100,6,FALSE) ), IF( OR( AND( VLOOKUP(C26,'Matches (สำหรับแอดมิน)'!$A$2:$G$100,5,FALSE)> VLOOKUP(C26,'Matches (สำหรับแอดมิน)'!$A$2:$G$100,6,FALSE), E26>G26 ), AND( VLOOKUP(C26,'Matches (สำหรับแอดมิน)'!$A$2:$G$100,6,FALSE)> VLOOKUP(C26,'Matches (สำหรับแอดมิน)'!$A$2:$G$100,5,FALSE), G26>E26 ), AND( VLOOKUP(C26,'Matches (สำหรับแอดมิน)'!$A$2:$G$100,5,FALSE)= VLOOKUP(C26,'Matches (สำหรับแอดมิน)'!$A$2:$G$100,6,FALSE), E26=G26 ) ), 3, 0 ) )) -> 0
A27: =B27&"_M"&C27 -> Aof_M3 | B27: Aof | C27: 3 | D27: =VLOOKUP(C27,'Matches (สำหรับแอดมิน)'!$A$2:$D$105,3,FALSE) -> Canada | E27: 0 | F27: =VLOOKUP(C27,'Matches (สำหรับแอดมิน)'!$A$2:$D$105,4,FALSE) -> Bosnia | G27: 2 | H27: =IF(VLOOKUP(C27,'Matches (สำหรับแอดมิน)'!$A$2:$G$100,7,FALSE)<>"จบแล้ว",0, IF( AND( E27=VLOOKUP(C27,'Matches (สำหรับแอดมิน)'!$A$2:$G$100,5,FALSE), G27=VLOOKUP(C27,'Matches (สำหรับแอดมิน)'!$A$2:$G$100,6,FALSE) ), IF( AND( VLOOKUP(C27,'Matches (สำหรับแอดมิน)'!$A$2:$G$100,5,FALSE)=0, VLOOKUP(C27,'Matches (สำหรับแอดมิน)'!$A$2:$G$100,6,FALSE)=0 ), 4, 3+ VLOOKUP(C27,'Matches (สำหรับแอดมิน)'!$A$2:$G$100,5,FALSE)+ VLOOKUP(C27,'Matches (สำหรับแอดมิน)'!$A$2:$G$100,6,FALSE) ), IF( OR( AND( VLOOKUP(C27,'Matches (สำหรับแอดมิน)'!$A$2:$G$100,5,FALSE)> VLOOKUP(C27,'Matches (สำหรับแอดมิน)'!$A$2:$G$100,6,FALSE), E27>G27 ), AND( VLOOKUP(C27,'Matches (สำหรับแอดมิน)'!$A$2:$G$100,6,FALSE)> VLOOKUP(C27,'Matches (สำหรับแอดมิน)'!$A$2:$G$100,5,FALSE), G27>E27 ), AND( VLOOKUP(C27,'Matches (สำหรับแอดมิน)'!$A$2:$G$100,5,FALSE)= VLOOKUP(C27,'Matches (สำหรับแอดมิน)'!$A$2:$G$100,6,FALSE), E27=G27 ) ), 3, 0 ) )) -> 0
A28: =B28&"_M"&C28 -> Ice_M3 | B28: Ice | C28: 3 | D28: =VLOOKUP(C28,'Matches (สำหรับแอดมิน)'!$A$2:$D$105,3,FALSE) -> Canada | F28: =VLOOKUP(C28,'Matches (สำหรับแอดมิน)'!$A$2:$D$105,4,FALSE) -> Bosnia | H28: =IF(VLOOKUP(C28,'Matches (สำหรับแอดมิน)'!$A$2:$G$100,7,FALSE)<>"จบแล้ว",0, IF( AND( E28=VLOOKUP(C28,'Matches (สำหรับแอดมิน)'!$A$2:$G$100,5,FALSE), G28=VLOOKUP(C28,'Matches (สำหรับแอดมิน)'!$A$2:$G$100,6,FALSE) ), IF( AND( VLOOKUP(C28,'Matches (สำหรับแอดมิน)'!$A$2:$G$100,5,FALSE)=0, VLOOKUP(C28,'Matches (สำหรับแอดมิน)'!$A$2:$G$100,6,FALSE)=0 ), 4, 3+ VLOOKUP(C28,'Matches (สำหรับแอดมิน)'!$A$2:$G$100,5,FALSE)+ VLOOKUP(C28,'Matches (สำหรับแอดมิน)'!$A$2:$G$100,6,FALSE) ), IF( OR( AND( VLOOKUP(C28,'Matches (สำหรับแอดมิน)'!$A$2:$G$100,5,FALSE)> VLOOKUP(C28,'Matches (สำหรับแอดมิน)'!$A$2:$G$100,6,FALSE), E28>G28 ), AND( VLOOKUP(C28,'Matches (สำหรับแอดมิน)'!$A$2:$G$100,6,FALSE)> VLOOKUP(C28,'Matches (สำหรับแอดมิน)'!$A$2:$G$100,5,FALSE), G28>E28 ), AND( VLOOKUP(C28,'Matches (สำหรับแอดมิน)'!$A$2:$G$100,5,FALSE)= VLOOKUP(C28,'Matches (สำหรับแอดมิน)'!$A$2:$G$100,6,FALSE), E28=G28 ) ), 3, 0 ) )) -> 0
A29: =B29&"_M"&C29 -> Golf_M3 | B29: Golf | C29: 3 | D29: =VLOOKUP(C29,'Matches (สำหรับแอดมิน)'!$A$2:$D$105,3,FALSE) -> Canada | F29: =VLOOKUP(C29,'Matches (สำหรับแอดมิน)'!$A$2:$D$105,4,FALSE) -> Bosnia | H29: =IF(VLOOKUP(C29,'Matches (สำหรับแอดมิน)'!$A$2:$G$100,7,FALSE)<>"จบแล้ว",0, IF( AND( E29=VLOOKUP(C29,'Matches (สำหรับแอดมิน)'!$A$2:$G$100,5,FALSE), G29=VLOOKUP(C29,'Matches (สำหรับแอดมิน)'!$A$2:$G$100,6,FALSE) ), IF( AND( VLOOKUP(C29,'Matches (สำหรับแอดมิน)'!$A$2:$G$100,5,FALSE)=0, VLOOKUP(C29,'Matches (สำหรับแอดมิน)'!$A$2:$G$100,6,FALSE)=0 ), 4, 3+ VLOOKUP(C29,'Matches (สำหรับแอดมิน)'!$A$2:$G$100,5,FALSE)+ VLOOKUP(C29,'Matches (สำหรับแอดมิน)'!$A$2:$G$100,6,FALSE) ), IF( OR( AND( VLOOKUP(C29,'Matches (สำหรับแอดมิน)'!$A$2:$G$100,5,FALSE)> VLOOKUP(C29,'Matches (สำหรับแอดมิน)'!$A$2:$G$100,6,FALSE), E29>G29 ), AND( VLOOKUP(C29,'Matches (สำหรับแอดมิน)'!$A$2:$G$100,6,FALSE)> VLOOKUP(C29,'Matches (สำหรับแอดมิน)'!$A$2:$G$100,5,FALSE), G29>E29 ), AND( VLOOKUP(C29,'Matches (สำหรับแอดมิน)'!$A$2:$G$100,5,FALSE)= VLOOKUP(C29,'Matches (สำหรับแอดมิน)'!$A$2:$G$100,6,FALSE), E29=G29 ) ), 3, 0 ) )) -> 0
A30: =B30&"_M"&C30 -> Mun_M3 | B30: Mun | C30: 3 | D30: =VLOOKUP(C30,'Matches (สำหรับแอดมิน)'!$A$2:$D$105,3,FALSE) -> Canada | F30: =VLOOKUP(C30,'Matches (สำหรับแอดมิน)'!$A$2:$D$105,4,FALSE) -> Bosnia | H30: =IF(VLOOKUP(C30,'Matches (สำหรับแอดมิน)'!$A$2:$G$100,7,FALSE)<>"จบแล้ว",0, IF( AND( E30=VLOOKUP(C30,'Matches (สำหรับแอดมิน)'!$A$2:$G$100,5,FALSE), G30=VLOOKUP(C30,'Matches (สำหรับแอดมิน)'!$A$2:$G$100,6,FALSE) ), IF( AND( VLOOKUP(C30,'Matches (สำหรับแอดมิน)'!$A$2:$G$100,5,FALSE)=0, VLOOKUP(C30,'Matches (สำหรับแอดมิน)'!$A$2:$G$100,6,FALSE)=0 ), 4, 3+ VLOOKUP(C30,'Matches (สำหรับแอดมิน)'!$A$2:$G$100,5,FALSE)+ VLOOKUP(C30,'Matches (สำหรับแอดมิน)'!$A$2:$G$100,6,FALSE) ), IF( OR( AND( VLOOKUP(C30,'Matches (สำหรับแอดมิน)'!$A$2:$G$100,5,FALSE)> VLOOKUP(C30,'Matches (สำหรับแอดมิน)'!$A$2:$G$100,6,FALSE), E30>G30 ), AND( VLOOKUP(C30,'Matches (สำหรับแอดมิน)'!$A$2:$G$100,6,FALSE)> VLOOKUP(C30,'Matches (สำหรับแอดมิน)'!$A$2:$G$100,5,FALSE), G30>E30 ), AND( VLOOKUP(C30,'Matches (สำหรับแอดมิน)'!$A$2:$G$100,5,FALSE)= VLOOKUP(C30,'Matches (สำหรับแอดมิน)'!$A$2:$G$100,6,FALSE), E30=G30 ) ), 3, 0 ) )) -> 0
A31: =B31&"_M"&C31 -> Mig_M3 | B31: Mig | C31: 3 | D31: =VLOOKUP(C31,'Matches (สำหรับแอดมิน)'!$A$2:$D$105,3,FALSE) -> Canada | F31: =VLOOKUP(C31,'Matches (สำหรับแอดมิน)'!$A$2:$D$105,4,FALSE) -> Bosnia | H31: =IF(VLOOKUP(C31,'Matches (สำหรับแอดมิน)'!$A$2:$G$100,7,FALSE)<>"จบแล้ว",0, IF( AND( E31=VLOOKUP(C31,'Matches (สำหรับแอดมิน)'!$A$2:$G$100,5,FALSE), G31=VLOOKUP(C31,'Matches (สำหรับแอดมิน)'!$A$2:$G$100,6,FALSE) ), IF( AND( VLOOKUP(C31,'Matches (สำหรับแอดมิน)'!$A$2:$G$100,5,FALSE)=0, VLOOKUP(C31,'Matches (สำหรับแอดมิน)'!$A$2:$G$100,6,FALSE)=0 ), 4, 3+ VLOOKUP(C31,'Matches (สำหรับแอดมิน)'!$A$2:$G$100,5,FALSE)+ VLOOKUP(C31,'Matches (สำหรับแอดมิน)'!$A$2:$G$100,6,FALSE) ), IF( OR( AND( VLOOKUP(C31,'Matches (สำหรับแอดมิน)'!$A$2:$G$100,5,FALSE)> VLOOKUP(C31,'Matches (สำหรับแอดมิน)'!$A$2:$G$100,6,FALSE), E31>G31 ), AND( VLOOKUP(C31,'Matches (สำหรับแอดมิน)'!$A$2:$G$100,6,FALSE)> VLOOKUP(C31,'Matches (สำหรับแอดมิน)'!$A$2:$G$100,5,FALSE), G31>E31 ), AND( VLOOKUP(C31,'Matches (สำหรับแอดมิน)'!$A$2:$G$100,5,FALSE)= VLOOKUP(C31,'Matches (สำหรับแอดมิน)'!$A$2:$G$100,6,FALSE), E31=G31 ) ), 3, 0 ) )) -> 0
A32: =B32&"_M"&C32 -> Ball_M4 | B32: Ball | C32: 4 | D32: =VLOOKUP(C32,'Matches (สำหรับแอดมิน)'!$A$2:$D$105,3,FALSE) -> United States | F32: =VLOOKUP(C32,'Matches (สำหรับแอดมิน)'!$A$2:$D$105,4,FALSE) -> Paraguay | H32: =IF(VLOOKUP(C32,'Matches (สำหรับแอดมิน)'!$A$2:$G$100,7,FALSE)<>"จบแล้ว",0, IF( AND( E32=VLOOKUP(C32,'Matches (สำหรับแอดมิน)'!$A$2:$G$100,5,FALSE), G32=VLOOKUP(C32,'Matches (สำหรับแอดมิน)'!$A$2:$G$100,6,FALSE) ), IF( AND( VLOOKUP(C32,'Matches (สำหรับแอดมิน)'!$A$2:$G$100,5,FALSE)=0, VLOOKUP(C32,'Matches (สำหรับแอดมิน)'!$A$2:$G$100,6,FALSE)=0 ), 4, 3+ VLOOKUP(C32,'Matches (สำหรับแอดมิน)'!$A$2:$G$100,5,FALSE)+ VLOOKUP(C32,'Matches (สำหรับแอดมิน)'!$A$2:$G$100,6,FALSE) ), IF( OR( AND( VLOOKUP(C32,'Matches (สำหรับแอดมิน)'!$A$2:$G$100,5,FALSE)> VLOOKUP(C32,'Matches (สำหรับแอดมิน)'!$A$2:$G$100,6,FALSE), E32>G32 ), AND( VLOOKUP(C32,'Matches (สำหรับแอดมิน)'!$A$2:$G$100,6,FALSE)> VLOOKUP(C32,'Matches (สำหรับแอดมิน)'!$A$2:$G$100,5,FALSE), G32>E32 ), AND( VLOOKUP(C32,'Matches (สำหรับแอดมิน)'!$A$2:$G$100,5,FALSE)= VLOOKUP(C32,'Matches (สำหรับแอดมิน)'!$A$2:$G$100,6,FALSE), E32=G32 ) ), 3, 0 ) )) -> 0
A33: =B33&"_M"&C33 -> Been_M4 | B33: Been | C33: 4 | D33: =VLOOKUP(C33,'Matches (สำหรับแอดมิน)'!$A$2:$D$105,3,FALSE) -> United States | F33: =VLOOKUP(C33,'Matches (สำหรับแอดมิน)'!$A$2:$D$105,4,FALSE) -> Paraguay | H33: =IF(VLOOKUP(C33,'Matches (สำหรับแอดมิน)'!$A$2:$G$100,7,FALSE)<>"จบแล้ว",0, IF( AND( E33=VLOOKUP(C33,'Matches (สำหรับแอดมิน)'!$A$2:$G$100,5,FALSE), G33=VLOOKUP(C33,'Matches (สำหรับแอดมิน)'!$A$2:$G$100,6,FALSE) ), IF( AND( VLOOKUP(C33,'Matches (สำหรับแอดมิน)'!$A$2:$G$100,5,FALSE)=0, VLOOKUP(C33,'Matches (สำหรับแอดมิน)'!$A$2:$G$100,6,FALSE)=0 ), 4, 3+ VLOOKUP(C33,'Matches (สำหรับแอดมิน)'!$A$2:$G$100,5,FALSE)+ VLOOKUP(C33,'Matches (สำหรับแอดมิน)'!$A$2:$G$100,6,FALSE) ), IF( OR( AND( VLOOKUP(C33,'Matches (สำหรับแอดมิน)'!$A$2:$G$100,5,FALSE)> VLOOKUP(C33,'Matches (สำหรับแอดมิน)'!$A$2:$G$100,6,FALSE), E33>G33 ), AND( VLOOKUP(C33,'Matches (สำหรับแอดมิน)'!$A$2:$G$100,6,FALSE)> VLOOKUP(C33,'Matches (สำหรับแอดมิน)'!$A$2:$G$100,5,FALSE), G33>E33 ), AND( VLOOKUP(C33,'Matches (สำหรับแอดมิน)'!$A$2:$G$100,5,FALSE)= VLOOKUP(C33,'Matches (สำหรับแอดมิน)'!$A$2:$G$100,6,FALSE), E33=G33 ) ), 3, 0 ) )) -> 0
A34: =B34&"_M"&C34 -> Faro_M4 | B34: Faro | C34: 4 | D34: =VLOOKUP(C34,'Matches (สำหรับแอดมิน)'!$A$2:$D$105,3,FALSE) -> United States | E34: 2 | F34: =VLOOKUP(C34,'Matches (สำหรับแอดมิน)'!$A$2:$D$105,4,FALSE) -> Paraguay | G34: 0 | H34: =IF(VLOOKUP(C34,'Matches (สำหรับแอดมิน)'!$A$2:$G$100,7,FALSE)<>"จบแล้ว",0, IF( AND( E34=VLOOKUP(C34,'Matches (สำหรับแอดมิน)'!$A$2:$G$100,5,FALSE), G34=VLOOKUP(C34,'Matches (สำหรับแอดมิน)'!$A$2:$G$100,6,FALSE) ), IF( AND( VLOOKUP(C34,'Matches (สำหรับแอดมิน)'!$A$2:$G$100,5,FALSE)=0, VLOOKUP(C34,'Matches (สำหรับแอดมิน)'!$A$2:$G$100,6,FALSE)=0 ), 4, 3+ VLOOKUP(C34,'Matches (สำหรับแอดมิน)'!$A$2:$G$100,5,FALSE)+ VLOOKUP(C34,'Matches (สำหรับแอดมิน)'!$A$2:$G$100,6,FALSE) ), IF( OR( AND( VLOOKUP(C34,'Matches (สำหรับแอดมิน)'!$A$2:$G$100,5,FALSE)> VLOOKUP(C34,'Matches (สำหรับแอดมิน)'!$A$2:$G$100,6,FALSE), E34>G34 ), AND( VLOOKUP(C34,'Matches (สำหรับแอดมิน)'!$A$2:$G$100,6,FALSE)> VLOOKUP(C34,'Matches (สำหรับแอดมิน)'!$A$2:$G$100,5,FALSE), G34>E34 ), AND( VLOOKUP(C34,'Matches (สำหรับแอดมิน)'!$A$2:$G$100,5,FALSE)= VLOOKUP(C34,'Matches (สำหรับแอดมิน)'!$A$2:$G$100,6,FALSE), E34=G34 ) ), 3, 0 ) )) -> 0
A35: =B35&"_M"&C35 -> Oat_M4 | B35: Oat | C35: 4 | D35: =VLOOKUP(C35,'Matches (สำหรับแอดมิน)'!$A$2:$D$105,3,FALSE) -> United States | E35: 1 | F35: =VLOOKUP(C35,'Matches (สำหรับแอดมิน)'!$A$2:$D$105,4,FALSE) -> Paraguay | G35: 1 | H35: =IF(VLOOKUP(C35,'Matches (สำหรับแอดมิน)'!$A$2:$G$100,7,FALSE)<>"จบแล้ว",0, IF( AND( E35=VLOOKUP(C35,'Matches (สำหรับแอดมิน)'!$A$2:$G$100,5,FALSE), G35=VLOOKUP(C35,'Matches (สำหรับแอดมิน)'!$A$2:$G$100,6,FALSE) ), IF( AND( VLOOKUP(C35,'Matches (สำหรับแอดมิน)'!$A$2:$G$100,5,FALSE)=0, VLOOKUP(C35,'Matches (สำหรับแอดมิน)'!$A$2:$G$100,6,FALSE)=0 ), 4, 3+ VLOOKUP(C35,'Matches (สำหรับแอดมิน)'!$A$2:$G$100,5,FALSE)+ VLOOKUP(C35,'Matches (สำหรับแอดมิน)'!$A$2:$G$100,6,FALSE) ), IF( OR( AND( VLOOKUP(C35,'Matches (สำหรับแอดมิน)'!$A$2:$G$100,5,FALSE)> VLOOKUP(C35,'Matches (สำหรับแอดมิน)'!$A$2:$G$100,6,FALSE), E35>G35 ), AND( VLOOKUP(C35,'Matches (สำหรับแอดมิน)'!$A$2:$G$100,6,FALSE)> VLOOKUP(C35,'Matches (สำหรับแอดมิน)'!$A$2:$G$100,5,FALSE), G35>E35 ), AND( VLOOKUP(C35,'Matches (สำหรับแอดมิน)'!$A$2:$G$100,5,FALSE)= VLOOKUP(C35,'Matches (สำหรับแอดมิน)'!$A$2:$G$100,6,FALSE), E35=G35 ) ), 3, 0 ) )) -> 0
A36: =B36&"_M"&C36 -> Kob_M4 | B36: Kob | C36: 4 | D36: =VLOOKUP(C36,'Matches (สำหรับแอดมิน)'!$A$2:$D$105,3,FALSE) -> United States | E36: 2 | F36: =VLOOKUP(C36,'Matches (สำหรับแอดมิน)'!$A$2:$D$105,4,FALSE) -> Paraguay | G36: 2 | H36: =IF(VLOOKUP(C36,'Matches (สำหรับแอดมิน)'!$A$2:$G$100,7,FALSE)<>"จบแล้ว",0, IF( AND( E36=VLOOKUP(C36,'Matches (สำหรับแอดมิน)'!$A$2:$G$100,5,FALSE), G36=VLOOKUP(C36,'Matches (สำหรับแอดมิน)'!$A$2:$G$100,6,FALSE) ), IF( AND( VLOOKUP(C36,'Matches (สำหรับแอดมิน)'!$A$2:$G$100,5,FALSE)=0, VLOOKUP(C36,'Matches (สำหรับแอดมิน)'!$A$2:$G$100,6,FALSE)=0 ), 4, 3+ VLOOKUP(C36,'Matches (สำหรับแอดมิน)'!$A$2:$G$100,5,FALSE)+ VLOOKUP(C36,'Matches (สำหรับแอดมิน)'!$A$2:$G$100,6,FALSE) ), IF( OR( AND( VLOOKUP(C36,'Matches (สำหรับแอดมิน)'!$A$2:$G$100,5,FALSE)> VLOOKUP(C36,'Matches (สำหรับแอดมิน)'!$A$2:$G$100,6,FALSE), E36>G36 ), AND( VLOOKUP(C36,'Matches (สำหรับแอดมิน)'!$A$2:$G$100,6,FALSE)> VLOOKUP(C36,'Matches (สำหรับแอดมิน)'!$A$2:$G$100,5,FALSE), G36>E36 ), AND( VLOOKUP(C36,'Matches (สำหรับแอดมิน)'!$A$2:$G$100,5,FALSE)= VLOOKUP(C36,'Matches (สำหรับแอดมิน)'!$A$2:$G$100,6,FALSE), E36=G36 ) ), 3, 0 ) )) -> 0
A37: =B37&"_M"&C37 -> Aof_M4 | B37: Aof | C37: 4 | D37: =VLOOKUP(C37,'Matches (สำหรับแอดมิน)'!$A$2:$D$105,3,FALSE) -> United States | E37: 1 | F37: =VLOOKUP(C37,'Matches (สำหรับแอดมิน)'!$A$2:$D$105,4,FALSE) -> Paraguay | G37: 4 | H37: =IF(VLOOKUP(C37,'Matches (สำหรับแอดมิน)'!$A$2:$G$100,7,FALSE)<>"จบแล้ว",0, IF( AND( E37=VLOOKUP(C37,'Matches (สำหรับแอดมิน)'!$A$2:$G$100,5,FALSE), G37=VLOOKUP(C37,'Matches (สำหรับแอดมิน)'!$A$2:$G$100,6,FALSE) ), IF( AND( VLOOKUP(C37,'Matches (สำหรับแอดมิน)'!$A$2:$G$100,5,FALSE)=0, VLOOKUP(C37,'Matches (สำหรับแอดมิน)'!$A$2:$G$100,6,FALSE)=0 ), 4, 3+ VLOOKUP(C37,'Matches (สำหรับแอดมิน)'!$A$2:$G$100,5,FALSE)+ VLOOKUP(C37,'Matches (สำหรับแอดมิน)'!$A$2:$G$100,6,FALSE) ), IF( OR( AND( VLOOKUP(C37,'Matches (สำหรับแอดมิน)'!$A$2:$G$100,5,FALSE)> VLOOKUP(C37,'Matches (สำหรับแอดมิน)'!$A$2:$G$100,6,FALSE), E37>G37 ), AND( VLOOKUP(C37,'Matches (สำหรับแอดมิน)'!$A$2:$G$100,6,FALSE)> VLOOKUP(C37,'Matches (สำหรับแอดมิน)'!$A$2:$G$100,5,FALSE), G37>E37 ), AND( VLOOKUP(C37,'Matches (สำหรับแอดมิน)'!$A$2:$G$100,5,FALSE)= VLOOKUP(C37,'Matches (สำหรับแอดมิน)'!$A$2:$G$100,6,FALSE), E37=G37 ) ), 3, 0 ) )) -> 0
A38: =B38&"_M"&C38 -> Ice_M4 | B38: Ice | C38: 4 | D38: =VLOOKUP(C38,'Matches (สำหรับแอดมิน)'!$A$2:$D$105,3,FALSE) -> United States | F38: =VLOOKUP(C38,'Matches (สำหรับแอดมิน)'!$A$2:$D$105,4,FALSE) -> Paraguay | H38: =IF(VLOOKUP(C38,'Matches (สำหรับแอดมิน)'!$A$2:$G$100,7,FALSE)<>"จบแล้ว",0, IF( AND( E38=VLOOKUP(C38,'Matches (สำหรับแอดมิน)'!$A$2:$G$100,5,FALSE), G38=VLOOKUP(C38,'Matches (สำหรับแอดมิน)'!$A$2:$G$100,6,FALSE) ), IF( AND( VLOOKUP(C38,'Matches (สำหรับแอดมิน)'!$A$2:$G$100,5,FALSE)=0, VLOOKUP(C38,'Matches (สำหรับแอดมิน)'!$A$2:$G$100,6,FALSE)=0 ), 4, 3+ VLOOKUP(C38,'Matches (สำหรับแอดมิน)'!$A$2:$G$100,5,FALSE)+ VLOOKUP(C38,'Matches (สำหรับแอดมิน)'!$A$2:$G$100,6,FALSE) ), IF( OR( AND( VLOOKUP(C38,'Matches (สำหรับแอดมิน)'!$A$2:$G$100,5,FALSE)> VLOOKUP(C38,'Matches (สำหรับแอดมิน)'!$A$2:$G$100,6,FALSE), E38>G38 ), AND( VLOOKUP(C38,'Matches (สำหรับแอดมิน)'!$A$2:$G$100,6,FALSE)> VLOOKUP(C38,'Matches (สำหรับแอดมิน)'!$A$2:$G$100,5,FALSE), G38>E38 ), AND( VLOOKUP(C38,'Matches (สำหรับแอดมิน)'!$A$2:$G$100,5,FALSE)= VLOOKUP(C38,'Matches (สำหรับแอดมิน)'!$A$2:$G$100,6,FALSE), E38=G38 ) ), 3, 0 ) )) -> 0
A39: =B39&"_M"&C39 -> Golf_M4 | B39: Golf | C39: 4 | D39: =VLOOKUP(C39,'Matches (สำหรับแอดมิน)'!$A$2:$D$105,3,FALSE) -> United States | F39: =VLOOKUP(C39,'Matches (สำหรับแอดมิน)'!$A$2:$D$105,4,FALSE) -> Paraguay | H39: =IF(VLOOKUP(C39,'Matches (สำหรับแอดมิน)'!$A$2:$G$100,7,FALSE)<>"จบแล้ว",0, IF( AND( E39=VLOOKUP(C39,'Matches (สำหรับแอดมิน)'!$A$2:$G$100,5,FALSE), G39=VLOOKUP(C39,'Matches (สำหรับแอดมิน)'!$A$2:$G$100,6,FALSE) ), IF( AND( VLOOKUP(C39,'Matches (สำหรับแอดมิน)'!$A$2:$G$100,5,FALSE)=0, VLOOKUP(C39,'Matches (สำหรับแอดมิน)'!$A$2:$G$100,6,FALSE)=0 ), 4, 3+ VLOOKUP(C39,'Matches (สำหรับแอดมิน)'!$A$2:$G$100,5,FALSE)+ VLOOKUP(C39,'Matches (สำหรับแอดมิน)'!$A$2:$G$100,6,FALSE) ), IF( OR( AND( VLOOKUP(C39,'Matches (สำหรับแอดมิน)'!$A$2:$G$100,5,FALSE)> VLOOKUP(C39,'Matches (สำหรับแอดมิน)'!$A$2:$G$100,6,FALSE), E39>G39 ), AND( VLOOKUP(C39,'Matches (สำหรับแอดมิน)'!$A$2:$G$100,6,FALSE)> VLOOKUP(C39,'Matches (สำหรับแอดมิน)'!$A$2:$G$100,5,FALSE), G39>E39 ), AND( VLOOKUP(C39,'Matches (สำหรับแอดมิน)'!$A$2:$G$100,5,FALSE)= VLOOKUP(C39,'Matches (สำหรับแอดมิน)'!$A$2:$G$100,6,FALSE), E39=G39 ) ), 3, 0 ) )) -> 0
A40: =B40&"_M"&C40 -> Mun_M4 | B40: Mun | C40: 4 | D40: =VLOOKUP(C40,'Matches (สำหรับแอดมิน)'!$A$2:$D$105,3,FALSE) -> United States | F40: =VLOOKUP(C40,'Matches (สำหรับแอดมิน)'!$A$2:$D$105,4,FALSE) -> Paraguay | H40: =IF(VLOOKUP(C40,'Matches (สำหรับแอดมิน)'!$A$2:$G$100,7,FALSE)<>"จบแล้ว",0, IF( AND( E40=VLOOKUP(C40,'Matches (สำหรับแอดมิน)'!$A$2:$G$100,5,FALSE), G40=VLOOKUP(C40,'Matches (สำหรับแอดมิน)'!$A$2:$G$100,6,FALSE) ), IF( AND( VLOOKUP(C40,'Matches (สำหรับแอดมิน)'!$A$2:$G$100,5,FALSE)=0, VLOOKUP(C40,'Matches (สำหรับแอดมิน)'!$A$2:$G$100,6,FALSE)=0 ), 4, 3+ VLOOKUP(C40,'Matches (สำหรับแอดมิน)'!$A$2:$G$100,5,FALSE)+ VLOOKUP(C40,'Matches (สำหรับแอดมิน)'!$A$2:$G$100,6,FALSE) ), IF( OR( AND( VLOOKUP(C40,'Matches (สำหรับแอดมิน)'!$A$2:$G$100,5,FALSE)> VLOOKUP(C40,'Matches (สำหรับแอดมิน)'!$A$2:$G$100,6,FALSE), E40>G40 ), AND( VLOOKUP(C40,'Matches (สำหรับแอดมิน)'!$A$2:$G$100,6,FALSE)> VLOOKUP(C40,'Matches (สำหรับแอดมิน)'!$A$2:$G$100,5,FALSE), G40>E40 ), AND( VLOOKUP(C40,'Matches (สำหรับแอดมิน)'!$A$2:$G$100,5,FALSE)= VLOOKUP(C40,'Matches (สำหรับแอดมิน)'!$A$2:$G$100,6,FALSE), E40=G40 ) ), 3, 0 ) )) -> 0
...

Sheet ผลคะแนน
A1: User_Email | B1: Total_Score
A2: Ball | B2: =SUMIF('Predictions (ทายผล)'!$B$2:$B$100, A2, 'Predictions (ทายผล)'!$H$2:$H$100) -> 0
A3: Been | B3: =SUMIF('Predictions (ทายผล)'!$B$2:$B$100, A3, 'Predictions (ทายผล)'!$H$2:$H$100) -> 0
A4: Faro | B4: =SUMIF('Predictions (ทายผล)'!$B$2:$B$100, A4, 'Predictions (ทายผล)'!$H$2:$H$100) -> 0
A5: Oat | B5: =SUMIF('Predictions (ทายผล)'!$B$2:$B$100, A5, 'Predictions (ทายผล)'!$H$2:$H$100) -> 0
A6: Kob | B6: =SUMIF('Predictions (ทายผล)'!$B$2:$B$100, A6, 'Predictions (ทายผล)'!$H$2:$H$100) -> 0
A7: Aof | B7: =SUMIF('Predictions (ทายผล)'!$B$2:$B$100, A7, 'Predictions (ทายผล)'!$H$2:$H$100) -> 0
A8: Ice | B8: =SUMIF('Predictions (ทายผล)'!$B$2:$B$100, A8, 'Predictions (ทายผล)'!$H$2:$H$100) -> 0
A9: Golf | B9: =SUMIF('Predictions (ทายผล)'!$B$2:$B$100, A9, 'Predictions (ทายผล)'!$H$2:$H$100) -> 0
A10: Mun | B10: =SUMIF('Predictions (ทายผล)'!$B$2:$B$100, A10, 'Predictions (ทายผล)'!$H$2:$H$100) -> 0
A11: Mig | B11: =SUMIF('Predictions (ทายผล)'!$B$2:$B$100, A11, 'Predictions (ทายผล)'!$H$2:$H$100) -> 0
